Workbook
Name CategoryOptions: 'Filter Lists'!$B$1:$B$3
Name CustomerOptions: 'Filter Lists'!$D$1:$D$28
Name ProductOptions: 'Filter Lists'!$C$1:$C$14
Name RegionOptions: 'Filter Lists'!$A$1:$A$5

Sheet Sales Dashboard
A1: SALES PERFORMANCE
A3: INTERACTIVE REPORT | Change green filter cells; KPI cards and all eight charts update in Excel. Amounts use source currency (unspecified).
B5: REGION | F5: CATEGORY | J5: PRODUCT | N5: CUSTOMER
B6: All | F6: All | J6: All | N6: All
A8: START DATE | B8: 45306 | E8: END DATE | F8: 46055 | I8: 33 records • 30 unique IDs • 6 conflicting-ID rows retained
A11: TOTAL SALES | G11: TOTAL PROFIT | M11: PROFIT MARGIN
A12: ='Calculations_KPIs'!B6 -> 1037200 | G12: ='Calculations_KPIs'!B8 -> 186700 | M12: ='Calculations_KPIs'!B9 -> 0.18000386
A16: UNIQUE ORDER IDs | G16: QUANTITY SOLD | M16: AVG ORDER VALUE
A17: ='Calculations_KPIs'!B10 -> 30 | G17: ='Calculations_KPIs'!B11 -> 96 | M17: ='Calculations_KPIs'!B12 -> 34573.333
A21: CAUTION: duplicate Order IDs retained as requested; revenue is provisional. Dates span Jan 2024–Feb 2026. Dropdown filters update dashboard only; use PivotTable field filters separately.

Sheet Executive Summary
A1: EXECUTIVE SUMMARY
A3: Management review | Full retained dataset | Findings are provisional where duplicate orders and source assumptions remain unresolved.
B6: 01 PERFORMANCE AT A GLANCE
B7: Total sales: 1,037,200 | Cost: 850,500 | Profit: 186,700 | Margin: 18.0%. The file contains 33 sales records, 30 distinct Order IDs and 96 units. AOV is 34,573.33 per distinct ID; average selling price is 10,804.17 per unit. Currency is not specified.
B12: 02 REVENUE & PROFIT LEADERS
B13: Mobile leads both revenue (267,000) and profit (40,000). Electronics leads category revenue (746,700; 72.0% of total) and profit (123,200), but its margin is 16.5% versus Furniture at 21.9%. Laptop generates 235,000 sales at a 12.8% margin: prioritize cost and pricing review rather than assuming high revenue means strong profitability.
B18: 03 REGIONAL PERFORMANCE
B19: North leads revenue (522,500; 50.4% share) and profit (76,500), but has the weakest regional margin (14.6%). West has the lowest revenue (148,200) and the strongest margin (23.8%); test expansion of its profitable mix. South margin is 22.6% and East margin is 18.1%. These comparisons are descriptive, not adjusted for product mix.
B24: 04 CUSTOMER VALUE
B25: C005 | Karan Yadav leads recorded sales (160,000) and profit (24,000), but both source rows share Order ID 1005. Validate this repetition before using the customer ranking for incentives. C001 | Amit Sharma follows with sales of 117,200 and profit of 18,200. Customer identification uses ID plus available names; missing first names are shown as Unknown.
B30: 05 TIME TRENDS & COVERAGE
B31: January 2025 is the highest recorded sales month (291,500) and profit month (50,500). Among months with records, March 2024 is the lowest sales (7,000) and profit (3,000). January 2026 is the lowest observed 2026 sales month (7,200). Missing months are displayed as zero supplied records in the dashboard, not verified zero business activity. The mixed and incomplete years do not support an overall growth conclusion.
B36: 06 COMPARABLE 2025 MONTHS
B37: Sales across January–April 2025: 291,500 → 146,000 → 175,000 → 165,500. April is 43.2% below January in the supplied records. Profit: 50,500 → 31,000 → 27,500 → 35,500; April profit is 29.1% below January but 29.1% above March. Coverage and duplicate-date conflicts limit trend interpretation; obtain a complete monthly extract.
... B66: TOP 5 CUSTOMERS | SALES & PROFIT
B67: Customer | F67: Sales | H67: Customer | L67: Profit
B68: C005 | Karan Yadav | F68: 160000 | H68: C005 | Karan Yadav | L68: 24000
B69: C001 | Amit Sharma | F69: 117200 | H69: C001 | Amit Sharma | L69: 18200
B70: C018 | Nitin Bansal | F70: 65000 | H70: C003 | Unknown Singh | L70: 11500
B71: C026 | Aditya Sethi | F71: 63000 | H71: C026 | Aditya Sethi | L71: 9000
B72: C008 | Pooja Agarwal | F72: 60000 | H72: C012 | Arjun Patel | L72: 9000

Sheet PivotTables
A1: PIVOTTABLE ANALYSIS
A3: Native Excel PivotTables | Full retained dataset | Refresh after source changes. Ratio margins beside each table use aggregated profit / sales.
A7: SALES BY PRODUCT
A8: Product | B8: Sales | C8: Quantity | D8: Profit | E8: Margin %
A9: Mobile | B9: 267000 | C9: 13 | D9: 40000 | E9: =IFERROR(D9/B9,0) -> 0.14981273
A10: Laptop | B10: 235000 | C10: 4 | D10: 30000 | E10: =IFERROR(D10/B10,0) -> 0.12765957
A11: Sofa | B11: 122000 | C11: 3 | D11: 21000 | E11: =IFERROR(D11/B11,0) -> 0.17213115
A12: Tablet | B12: 92000 | C12: 5 | D12: 15000 | E12: =IFERROR(D12/B12,0) -> 0.16304348
A13: Monitor | B13: 72000 | C13: 5 | D13: 12000 | E13: =IFERROR(D13/B13,0) -> 0.16666667
A14: Chair | B14: 68000 | C14: 17 | D14: 19000 | E14: =IFERROR(D14/B14,0) -> 0.27941176
A15: Table | B15: 46000 | C15: 6 | D15: 7000 | E15: =IFERROR(D15/B15,0) -> 0.15217391
A16: Printer | B16: 34000 | C16: 3 | D16: 8000 | E16: =IFERROR(D16/B16,0) -> 0.23529412
A17: Bookshelf | B17: 28000 | C17: 4 | D17: 9000 | E17: =IFERROR(D17/B17,0) -> 0.32142857
A18: Desk | B18: 26500 | C18: 3 | D18: 7500 | E18: =IFERROR(D18/B18,0) -> 0.28301887
A19: Headphones | B19: 22500 | C19: 8 | D19: 8000 | E19: =IFERROR(D19/B19,0) -> 0.35555556
A20: Keyboard | B20: 13200 | C20: 10 | D20: 5700 | E20: =IFERROR(D20/B20,0) -> 0.43181818
... A22: Grand Total | B22: 1037200 | C22: 96 | D22: 186700 | E22: =IFERROR(D22/B22,0) -> 0.18000386
A26: SALES BY CATEGORY
A27: Category | B27: Sales | C27: Cost | D27: Profit | E27: Quantity | F27: Margin %
A28: Electronics | B28: 746700 | C28: 623500 | D28: 123200 | E28: 63 | F28: =IFERROR(D28/B28,0) -> 0.16499263
A29: Furniture | B29: 290500 | C29: 227000 | D29: 63500 | E29: 33 | F29: =IFERROR(D29/B29,0) -> 0.21858864
A30: Grand Total | B30: 1037200 | C30: 850500 | D30: 186700 | E30: 96 | F30: =IFERROR(D30/B30,0) -> 0.18000386
A34: SALES BY REGION
A35: Region | B35: Sales | C35: Profit | D35: Quantity | E35: Sales records | F35: Margin %
A36: North | B36: 522500 | C36: 76500 | D36: 19 | E36: 9 | F36: =IFERROR(C36/B36,0) -> 0.14641148
A37: South | B37: 190000 | C37: 43000 | D37: 28 | E37: 8 | F37: =IFERROR(C37/B37,0) -> 0.22631579
A38: East | B38: 176500 | C38: 32000 | D38: 15 | E38: 8 | F38: =IFERROR(C38/B38,0) -> 0.18130312
A39: West | B39: 148200 | C39: 35200 | D39: 34 | E39: 8 | F39: =IFERROR(C39/B39,0) -> 0.23751687
A40: Grand Total | B40: 1037200 | C40: 186700 | D40: 96 | E40: 33 | F40: =IFERROR(C40/B40,0) -> 0.18000386
A44: MONTHLY SALES TREND
A45: Month | B45: Sales | C45: Profit | D45: Sales records | E45: Margin %
A46: 2024-01 | B46: 80000 | C46: 12000 | D46: 1 | E46: =IFERROR(C46/B46,0) -> 0.15
A47: 2024-02 | B47: 42000 | C47: 7000 | D47: 1 | E47: =IFERROR(C47/B47,0) -> 0.16666667
A48: 2024-03 | B48: 7000 | C48: 3000 | D48: 1 | E48: =IFERROR(C48/B48,0) -> 0.42857143
A49: 2024-04 | B49: 63000 | C49: 9000 | D49: 1 | E49: =IFERROR(C49/B49,0) -> 0.14285714
A50: 2025-01 | B50: 291500 | C50: 50500 | D50: 9 | E50: =IFERROR(C50/B50,0) -> 0.17324185
A51: 2025-02 | B51: 146000 | C51: 31000 | D51: 6 | E51: =IFERROR(C51/B51,0) -> 0.21232877
A52: 2025-03 | B52: 175000 | C52: 27500 | D52: 5 | E52: =IFERROR(C52/B52,0) -> 0.15714286
A53: 2025-04 | B53: 165500 | C53: 35500 | D53: 7 | E53: =IFERROR(C53/B53,0) -> 0.21450151
A54: 2026-01 | B54: 7200 | C54: 3200 | D54: 1 | E54: =IFERROR(C54/B54,0) -> 0.44444444
...

Sheet Calculations_KPIs
A1: KPI ENGINE & CHART SOURCES
A3: Live SUMIFS calculations use dashboard filters. Unique orders are counted within each selected slice; record counts are shown separately.
A6: Total Sales | B6: =SUMIFS('Cleaned Data'!$K$2:$K$34,'Cleaned Data'!$H$2:$H$34,IF('Sales Dashboard'!$B$6="All","*",'Sales Dashboard'!$B$6),'Cleaned Data'!$G$2:$G$34,IF('Sales Dashboard'!$F$6="All","*",'Sales Dashboard'!$F$6),'Cleaned Data'!$F$2:$F$34,IF('Sales Dashboard'!$J$6="All","*",'Sales Dashboard'!$J$6),'Cleaned Data'!$Q$2:$Q$34,IF('Sales Dashboard'!$N$6="All","*",'Sales Dashboard'!$N$6),'Cleaned Data'!$B$2:$B$34,">="&'Sales Dashboard'!$B$8,'Cleaned Data'!$B$2:$B$34,"<="&'Sales Dashboard'!$F$8) -> 1037200 | D6: Definition notes: Total Sales = sum of Quantity × Price. Total Cost = sum of supplied line costs (not per-unit costs). Profit = Sales − Cost. Margin = total Profit / total Sales. AOV = total Sales / distinct Order IDs. Retained duplicate IDs may overstate sales.
A7: Total Cost | B7: =SUMIFS('Cleaned Data'!$L$2:$L$34,'Cleaned Data'!$H$2:$H$34,IF('Sales Dashboard'!$B$6="All","*",'Sales Dashboard'!$B$6),'Cleaned Data'!$G$2:$G$34,IF('Sales Dashboard'!$F$6="All","*",'Sales Dashboard'!$F$6),'Cleaned Data'!$F$2:$F$34,IF('Sales Dashboard'!$J$6="All","*",'Sales Dashboard'!$J$6),'Cleaned Data'!$Q$2:$Q$34,IF('Sales Dashboard'!$N$6="All","*",'Sales Dashboard'!$N$6),'Cleaned Data'!$B$2:$B$34,">="&'Sales Dashboard'!$B$8,'Cleaned Data'!$B$2:$B$34,"<="&'Sales Dashboard'!$F$8) -> 850500
A8: Total Profit | B8: =SUMIFS('Cleaned Data'!$M$2:$M$34,'Cleaned Data'!$H$2:$H$34,IF('Sales Dashboard'!$B$6="All","*",'Sales Dashboard'!$B$6),'Cleaned Data'!$G$2:$G$34,IF('Sales Dashboard'!$F$6="All","*",'Sales Dashboard'!$F$6),'Cleaned Data'!$F$2:$F$34,IF('Sales Dashboard'!$J$6="All","*",'Sales Dashboard'!$J$6),'Cleaned Data'!$Q$2:$Q$34,IF('Sales Dashboard'!$N$6="All","*",'Sales Dashboard'!$N$6),'Cleaned Data'!$B$2:$B$34,">="&'Sales Dashboard'!$B$8,'Cleaned Data'!$B$2:$B$34,"<="&'Sales Dashboard'!$F$8) -> 186700
A9: Profit Margin % | B9: =IFERROR(B8/B6,0) -> 0.18000386
A10: Unique Order IDs | B10: =SUMPRODUCT((IF('Sales Dashboard'!$B$6="All",1,--('Cleaned Data'!$H$2:$H$34='Sales Dashboard'!$B$6))*IF('Sales Dashboard'!$F$6="All",1,--('Cleaned Data'!$G$2:$G$34='Sales Dashboard'!$F$6))*IF('Sales Dashboard'!$J$6="All",1,--('Cleaned Data'!$F$2:$F$34='Sales Dashboard'!$J$6))*IF('Sales Dashboard'!$N$6="All",1,--('Cleaned Data'!$Q$2:$Q$34='Sales Dashboard'!$N$6))*--('Cleaned Data'!$B$2:$B$34>='Sales Dashboard'!$B$8)*--('Cleaned Data'!$B$2:$B$34<='Sales Dashboard'!$F$8))/(COUNTIFS('Cleaned Data'!$A$2:$A$34,'Cleaned Data'!$A$2:$A$34,'Cleaned Data'!$H$2:$H$34,IF('Sales Dashboard'!$B$6="All","*",'Sales Dashboard'!$B$6),'Cleaned Data'!$G$2:$G$34,IF('Sales Dashboard'!$F$6="All","*",'Sales Dashboard'!$F$6),'Cleaned Data'!$F$2:$F$34,IF('Sales Dashboard'!$J$6="All","*",'Sales Dashboard'!$J$6),'Cleaned Data'!$Q$2:$Q$34,IF('Sales Dashboard'!$N$6="All","*",'Sales Dashboard'!$N$6),'Cleaned Data'!$B$2:$B$34,">="&'Sales Dashboard'!$B$8,'Cleaned Data'!$B$2:$B$34,"<="&'Sales Dashboard'!$F$8)+1-(IF('Sales Dashboard'!$B$6="All",1,--('Cleaned Data'!$H$2:$H$34='Sales Dashboard'!$B$6))*IF('Sales Dashboard'!$F$6="All",1,--('Cleaned Data'!$G$2:$G$34='Sales Dashboard'!$F$6))*IF('Sales Dashboard'!$J$6="All",1,--('Cleaned Data'!$F$2:$F$34='Sales Dashboard'!$J$6))*IF('Sales Dashboard'!$N$6="All",1,--('Cleaned Data'!$Q$2:$Q$34='Sales Dashboard'!$N$6))*--('Cleaned Data'!$B$2:$B$34>='Sales Dashboard'!$B$8)*--('Cleaned Data'!$B$2:$B$34<='Sales Dashboard'!$F$8)))) -> 30
A11: Quantity Sold | B11: =SUMIFS('Cleaned Data'!$I$2:$I$34,'Cleaned Data'!$H$2:$H$34,IF('Sales Dashboard'!$B$6="All","*",'Sales Dashboard'!$B$6),'Cleaned Data'!$G$2:$G$34,IF('Sales Dashboard'!$F$6="All","*",'Sales Dashboard'!$F$6),'Cleaned Data'!$F$2:$F$34,IF('Sales Dashboard'!$J$6="All","*",'Sales Dashboard'!$J$6),'Cleaned Data'!$Q$2:$Q$34,IF('Sales Dashboard'!$N$6="All","*",'Sales Dashboard'!$N$6),'Cleaned Data'!$B$2:$B$34,">="&'Sales Dashboard'!$B$8,'Cleaned Data'!$B$2:$B$34,"<="&'Sales Dashboard'!$F$8) -> 96 | D11: No currency symbol is assumed. Unknown first names remain unresolved. Zero-sales months represent no supplied records, not confirmed business inactivity. PivotTables are full-dataset snapshots and have their own Excel field filters; dashboard dropdowns drive the KPI engine and charts.
A12: Average Order Value | B12: =IFERROR(B6/B10,0) -> 34573.333
A13: Average Selling Price | B13: =IFERROR(B6/B11,0) -> 10804.167
A14: Sales Records | B14: =COUNTIFS('Cleaned Data'!$H$2:$H$34,IF('Sales Dashboard'!$B$6="All","*",'Sales Dashboard'!$B$6),'Cleaned Data'!$G$2:$G$34,IF('Sales Dashboard'!$F$6="All","*",'Sales Dashboard'!$F$6),'Cleaned Data'!$F$2:$F$34,IF('Sales Dashboard'!$J$6="All","*",'Sales Dashboard'!$J$6),'Cleaned Data'!$Q$2:$Q$34,IF('Sales Dashboard'!$N$6="All","*",'Sales Dashboard'!$N$6),'Cleaned Data'!$B$2:$B$34,">="&'Sales Dashboard'!$B$8,'Cleaned Data'!$B$2:$B$34,"<="&'Sales Dashboard'!$F$8) -> 33
A18: PRODUCT | FILTER-RESPONSIVE ANALYSIS
A19: Product | B19: Sales | C19: Cost | D19: Profit | E19: Quantity | F19: Records | G19: Orders | H19: Margin %
A20: Mobile | B20: =SUMIFS('Cleaned Data'!$K$2:$K$34,'Cleaned Data'!$H$2:$H$34,IF('Sales Dashboard'!$B$6="All","*",'Sales Dashboard'!$B$6),'Cleaned Data'!$G$2:$G$34,IF('Sales Dashboard'!$F$6="All","*",'Sales Dashboard'!$F$6),'Cleaned Data'!$F$2:$F$34,IF('Sales Dashboard'!$J$6="All","*",'Sales Dashboard'!$J$6),'Cleaned Data'!$Q$2:$Q$34,IF('Sales Dashboard'!$N$6="All","*",'Sales Dashboard'!$N$6),'Cleaned Data'!$B$2:$B$34,">="&'Sales Dashboard'!$B$8,'Cleaned Data'!$B$2:$B$34,"<="&'Sales Dashboard'!$F$8,'Cleaned Data'!$F$2:$F$34,A20) -> 267000 | C20: =SUMIFS('Cleaned Data'!$L$2:$L$34,'Cleaned Data'!$H$2:$H$34,IF('Sales Dashboard'!$B$6="All","*",'Sales Dashboard'!$B$6),'Cleaned Data'!$G$2:$G$34,IF('Sales Dashboard'!$F$6="All","*",'Sales Dashboard'!$F$6),'Cleaned Data'!$F$2:$F$34,IF('Sales Dashboard'!$J$6="All","*",'Sales Dashboard'!$J$6),'Cleaned Data'!$Q$2:$Q$34,IF('Sales Dashboard'!$N$6="All","*",'Sales Dashboard'!$N$6),'Cleaned Data'!$B$2:$B$34,">="&'Sales Dashboard'!$B$8,'Cleaned Data'!$B$2:$B$34,"<="&'Sales Dashboard'!$F$8,'Cleaned Data'!$F$2:$F$34,A20) -> 227000 | D20: =SUMIFS('Cleaned Data'!$M$2:$M$34,'Cleaned Data'!$H$2:$H$34,IF('Sales Dashboard'!$B$6="All","*",'Sales Dashboard'!$B$6),'Cleaned Data'!$G$2:$G$34,IF('Sales Dashboard'!$F$6="All","*",'Sales Dashboard'!$F$6),'Cleaned Data'!$F$2:$F$34,IF('Sales Dashboard'!$J$6="All","*",'Sales Dashboard'!$J$6),'Cleaned Data'!$Q$2:$Q$34,IF('Sales Dashboard'!$N$6="All","*",'Sales Dashboard'!$N$6),'Cleaned Data'!$B$2:$B$34,">="&'Sales Dashboard'!$B$8,'Cleaned Data'!$B$2:$B$34,"<="&'Sales Dashboard'!$F$8,'Cleaned Data'!$F$2:$F$34,A20) -> 40000 | E20: =SUMIFS('Cleaned Data'!$I$2:$I$34,'Cleaned Data'!$H$2:$H$34,IF('Sales Dashboard'!$B$6="All","*",'Sales Dashboard'!$B$6),'Cleaned Data'!$G$2:$G$34,IF('Sales Dashboard'!$F$6="All","*",'Sales Dashboard'!$F$6),'Cleaned Data'!$F$2:$F$34,IF('Sales Dashboard'!$J$6="All","*",'Sales Dashboard'!$J$6),'Cleaned Data'!$Q$2:$Q$34,IF('Sales Dashboard'!$N$6="All","*",'Sales Dashboard'!$N$6),'Cleaned Data'!$B$2:$B$34,">="&'Sales Dashboard'!$B$8,'Cleaned Data'!$B$2:$B$34,"<="&'Sales Dashboard'!$F$8,'Cleaned Data'!$F$2:$F$34,A20) -> 13 | F20: =COUNTIFS('Cleaned Data'!$H$2:$H$34,IF('Sales Dashboard'!$B$6="All","*",'Sales Dashboard'!$B$6),'Cleaned Data'!$G$2:$G$34,IF('Sales Dashboard'!$F$6="All","*",'Sales Dashboard'!$F$6),'Cleaned Data'!$F$2:$F$34,IF('Sales Dashboard'!$J$6="All","*",'Sales Dashboard'!$J$6),'Cleaned Data'!$Q$2:$Q$34,IF('Sales Dashboard'!$N$6="All","*",'Sales Dashboard'!$N$6),'Cleaned Data'!$B$2:$B$34,">="&'Sales Dashboard'!$B$8,'Cleaned Data'!$B$2:$B$34,"<="&'Sales Dashboard'!$F$8,'Cleaned Data'!$F$2:$F$34,A20) -> 4 | G20: =SUMPRODUCT(((IF('Sales Dashboard'!$B$6="All",1,--('Cleaned Data'!$H$2:$H$34='Sales Dashboard'!$B$6))*IF('Sales Dashboard'!$F$6="All",1,--('Cleaned Data'!$G$2:$G$34='Sales Dashboard'!$F$6))*IF('Sales Dashboard'!$J$6="All",1,--('Cleaned Data'!$F$2:$F$34='Sales Dashboard'!$J$6))*IF('Sales Dashboard'!$N$6="All",1,--('Cleaned Data'!$Q$2:$Q$34='Sales Dashboard'!$N$6))*--('Cleaned Data'!$B$2:$B$34>='Sales Dashboard'!$B$8)*--('Cleaned Data'!$B$2:$B$34<='Sales Dashboard'!$F$8))*--('Cleaned Data'!$F$2:$F$34=A20))/(COUNTIFS('Cleaned Data'!$A$2:$A$34,'Cleaned Data'!$A$2:$A$34,'Cleaned Data'!$H$2:$H$34,IF('Sales Dashboard'!$B$6="All","*",'Sales Dashboard'!$B$6),'Cleaned Data'!$G$2:$G$34,IF('Sales Dashboard'!$F$6="All","*",'Sales Dashboard'!$F$6),'Cleaned Data'!$F$2:$F$34,IF('Sales Dashboard'!$J$6="All","*",'Sales Dashboard'!$J$6),'Cleaned Data'!$Q$2:$Q$34,IF('Sales Dashboard'!$N$6="All","*",'Sales Dashboard'!$N$6),'Cleaned Data'!$B$2:$B$34,">="&'Sales Dashboard'!$B$8,'Cleaned Data'!$B$2:$B$34,"<="&'Sales Dashboard'!$F$8,'Cleaned Data'!$F$2:$F$34,A20)+1-((IF('Sales Dashboard'!$B$6="All",1,--('Cleaned Data'!$H$2:$H$34='Sales Dashboard'!$B$6))*IF('Sales Dashboard'!$F$6="All",1,--('Cleaned Data'!$G$2:$G$34='Sales Dashboard'!$F$6))*IF('Sales Dashboard'!$J$6="All",1,--('Cleaned Data'!$F$2:$F$34='Sales Dashboard'!$J$6))*IF('Sales Dashboard'!$N$6="All",1,--('Cleaned Data'!$Q$2:$Q$34='Sales Dashboard'!$N$6))*--('Cleaned Data'!$B$2:$B$34>='Sales Dashboard'!$B$8)*--('Cleaned Data'!$B$2:$B$34<='Sales Dashboard'!$F$8))*--('Cleaned Data'!$F$2:$F$34=A20)))) -> 3 | H20: =IFERROR(D20/B20,0) -> 0.14981273
A21: Laptop | B21: =SUMIFS('Cleaned Data'!$K$2:$K$34,'Cleaned Data'!$H$2:$H$34,IF('Sales Dashboard'!$B$6="All","*",'Sales Dashboard'!$B$6),'Cleaned Data'!$G$2:$G$34,IF('Sales Dashboard'!$F$6="All","*",'Sales Dashboard'!$F$6),'Cleaned Data'!$F$2:$F$34,IF('Sales Dashboard'!$J$6="All","*",'Sales Dashboard'!$J$6),'Cleaned Data'!$Q$2:$Q$34,IF('Sales Dashboard'!$N$6="All","*",'Sales Dashboard'!$N$6),'Cleaned Data'!$B$2:$B$34,">="&'Sales Dashboard'!$B$8,'Cleaned Data'!$B$2:$B$34,"<="&'Sales Dashboard'!$F$8,'Cleaned Data'!$F$2:$F$34,A21) -> 235000 | C21: =SUMIFS('Cleaned Data'!$L$2:$L$34,'Cleaned Data'!$H$2:$H$34,IF('Sales Dashboard'!$B$6="All","*",'Sales Dashboard'!$B$6),'Cleaned Data'!$G$2:$G$34,IF('Sales Dashboard'!$F$6="All","*",'Sales Dashboard'!$F$6),'Cleaned Data'!$F$2:$F$34,IF('Sales Dashboard'!$J$6="All","*",'Sales Dashboard'!$J$6),'Cleaned Data'!$Q$2:$Q$34,IF('Sales Dashboard'!$N$6="All","*",'Sales Dashboard'!$N$6),'Cleaned Data'!$B$2:$B$34,">="&'Sales Dashboard'!$B$8,'Cleaned Data'!$B$2:$B$34,"<="&'Sales Dashboard'!$F$8,'Cleaned Data'!$F$2:$F$34,A21) -> 205000 | D21: =SUMIFS('Cleaned Data'!$M$2:$M$34,'Cleaned Data'!$H$2:$H$34,IF('Sales Dashboard'!$B$6="All","*",'Sales Dashboard'!$B$6),'Cleaned Data'!$G$2:$G$34,IF('Sales Dashboard'!$F$6="All","*",'Sales Dashboard'!$F$6),'Cleaned Data'!$F$2:$F$34,IF('Sales Dashboard'!$J$6="All","*",'Sales Dashboard'!$J$6),'Cleaned Data'!$Q$2:$Q$34,IF('Sales Dashboard'!$N$6="All","*",'Sales Dashboard'!$N$6),'Cleaned Data'!$B$2:$B$34,">="&'Sales Dashboard'!$B$8,'Cleaned Data'!$B$2:$B$34,"<="&'Sales Dashboard'!$F$8,'Cleaned Data'!$F$2:$F$34,A21) -> 30000 | E21: =SUMIFS('Cleaned Data'!$I$2:$I$34,'Cleaned Data'!$H$2:$H$34,IF('Sales Dashboard'!$B$6="All","*",'Sales Dashboard'!$B$6),'Cleaned Data'!$G$2:$G$34,IF('Sales Dashboard'!$F$6="All","*",'Sales Dashboard'!$F$6),'Cleaned Data'!$F$2:$F$34,IF('Sales Dashboard'!$J$6="All","*",'Sales Dashboard'!$J$6),'Cleaned Data'!$Q$2:$Q$34,IF('Sales Dashboard'!$N$6="All","*",'Sales Dashboard'!$N$6),'Cleaned Data'!$B$2:$B$34,">="&'Sales Dashboard'!$B$8,'Cleaned Data'!$B$2:$B$34,"<="&'Sales Dashboard'!$F$8,'Cleaned Data'!$F$2:$F$34,A21) -> 4 | F21: =COUNTIFS('Cleaned Data'!$H$2:$H$34,IF('Sales Dashboard'!$B$6="All","*",'Sales Dashboard'!$B$6),'Cleaned Data'!$G$2:$G$34,IF('Sales Dashboard'!$F$6="All","*",'Sales Dashboard'!$F$6),'Cleaned Data'!$F$2:$F$34,IF('Sales Dashboard'!$J$6="All","*",'Sales Dashboard'!$J$6),'Cleaned Data'!$Q$2:$Q$34,IF('Sales Dashboard'!$N$6="All","*",'Sales Dashboard'!$N$6),'Cleaned Data'!$B$2:$B$34,">="&'Sales Dashboard'!$B$8,'Cleaned Data'!$B$2:$B$34,"<="&'Sales Dashboard'!$F$8,'Cleaned Data'!$F$2:$F$34,A21) -> 3 | G21: =SUMPRODUCT(((IF('Sales Dashboard'!$B$6="All",1,--('Cleaned Data'!$H$2:$H$34='Sales Dashboard'!$B$6))*IF('Sales Dashboard'!$F$6="All",1,--('Cleaned Data'!$G$2:$G$34='Sales Dashboard'!$F$6))*IF('Sales Dashboard'!$J$6="All",1,--('Cleaned Data'!$F$2:$F$34='Sales Dashboard'!$J$6))*IF('Sales Dashboard'!$N$6="All",1,--('Cleaned Data'!$Q$2:$Q$34='Sales Dashboard'!$N$6))*--('Cleaned Data'!$B$2:$B$34>='Sales Dashboard'!$B$8)*--('Cleaned Data'!$B$2:$B$34<='Sales Dashboard'!$F$8))*--('Cleaned Data'!$F$2:$F$34=A21))/(COUNTIFS('Cleaned Data'!$A$2:$A$34,'Cleaned Data'!$A$2:$A$34,'Cleaned Data'!$H$2:$H$34,IF('Sales Dashboard'!$B$6="All","*",'Sales Dashboard'!$B$6),'Cleaned Data'!$G$2:$G$34,IF('Sales Dashboard'!$F$6="All","*",'Sales Dashboard'!$F$6),'Cleaned Data'!$F$2:$F$34,IF('Sales Dashboard'!$J$6="All","*",'Sales Dashboard'!$J$6),'Cleaned Data'!$Q$2:$Q$34,IF('Sales Dashboard'!$N$6="All","*",'Sales Dashboard'!$N$6),'Cleaned Data'!$B$2:$B$34,">="&'Sales Dashboard'!$B$8,'Cleaned Data'!$B$2:$B$34,"<="&'Sales Dashboard'!$F$8,'Cleaned Data'!$F$2:$F$34,A21)+1-((IF('Sales Dashboard'!$B$6="All",1,--('Cleaned Data'!$H$2:$H$34='Sales Dashboard'!$B$6))*IF('Sales Dashboard'!$F$6="All",1,--('Cleaned Data'!$G$2:$G$34='Sales Dashboard'!$F$6))*IF('Sales Dashboard'!$J$6="All",1,--('Cleaned Data'!$F$2:$F$34='Sales Dashboard'!$J$6))*IF('Sales Dashboard'!$N$6="All",1,--('Cleaned Data'!$Q$2:$Q$34='Sales Dashboard'!$N$6))*--('Cleaned Data'!$B$2:$B$34>='Sales Dashboard'!$B$8)*--('Cleaned Data'!$B$2:$B$34<='Sales Dashboard'!$F$8))*--('Cleaned Data'!$F$2:$F$34=A21)))) -> 3 | H21: =IFERROR(D21/B21,0) -> 0.12765957
A22: Sofa | B22: =SUMIFS('Cleaned Data'!$K$2:$K$34,'Cleaned Data'!$H$2:$H$34,IF('Sales Dashboard'!$B$6="All","*",'Sales Dashboard'!$B$6),'Cleaned Data'!$G$2:$G$34,IF('Sales Dashboard'!$F$6="All","*",'Sales Dashboard'!$F$6),'Cleaned Data'!$F$2:$F$34,IF('Sales Dashboard'!$J$6="All","*",'Sales Dashboard'!$J$6),'Cleaned Data'!$Q$2:$Q$34,IF('Sales Dashboard'!$N$6="All","*",'Sales Dashboard'!$N$6),'Cleaned Data'!$B$2:$B$34,">="&'Sales Dashboard'!$B$8,'Cleaned Data'!$B$2:$B$34,"<="&'Sales Dashboard'!$F$8,'Cleaned Data'!$F$2:$F$34,A22) -> 122000 | C22: =SUMIFS('Cleaned Data'!$L$2:$L$34,'Cleaned Data'!$H$2:$H$34,IF('Sales Dashboard'!$B$6="All","*",'Sales Dashboard'!$B$6),'Cleaned Data'!$G$2:$G$34,IF('Sales Dashboard'!$F$6="All","*",'Sales Dashboard'!$F$6),'Cleaned Data'!$F$2:$F$34,IF('Sales Dashboard'!$J$6="All","*",'Sales Dashboard'!$J$6),'Cleaned Data'!$Q$2:$Q$34,IF('Sales Dashboard'!$N$6="All","*",'Sales Dashboard'!$N$6),'Cleaned Data'!$B$2:$B$34,">="&'Sales Dashboard'!$B$8,'Cleaned Data'!$B$2:$B$34,"<="&'Sales Dashboard'!$F$8,'Cleaned Data'!$F$2:$F$34,A22) -> 101000 | D22: =SUMIFS('Cleaned Data'!$M$2:$M$34,'Cleaned Data'!$H$2:$H$34,IF('Sales Dashboard'!$B$6="All","*",'Sales Dashboard'!$B$6),'Cleaned Data'!$G$2:$G$34,IF('Sales Dashboard'!$F$6="All","*",'Sales Dashboard'!$F$6),'Cleaned Data'!$F$2:$F$34,IF('Sales Dashboard'!$J$6="All","*",'Sales Dashboard'!$J$6),'Cleaned Data'!$Q$2:$Q$34,IF('Sales Dashboard'!$N$6="All","*",'Sales Dashboard'!$N$6),'Cleaned Data'!$B$2:$B$34,">="&'Sales Dashboard'!$B$8,'Cleaned Data'!$B$2:$B$34,"<="&'Sales Dashboard'!$F$8,'Cleaned Data'!$F$2:$F$34,A22) -> 21000 | E22: =SUMIFS('Cleaned Data'!$I$2:$I$34,'Cleaned Data'!$H$2:$H$34,IF('Sales Dashboard'!$B$6="All","*",'Sales Dashboard'!$B$6),'Cleaned Data'!$G$2:$G$34,IF('Sales Dashboard'!$F$6="All","*",'Sales Dashboard'!$F$6),'Cleaned Data'!$F$2:$F$34,IF('Sales Dashboard'!$J$6="All","*",'Sales Dashboard'!$J$6),'Cleaned Data'!$Q$2:$Q$34,IF('Sales Dashboard'!$N$6="All","*",'Sales Dashboard'!$N$6),'Cleaned Data'!$B$2:$B$34,">="&'Sales Dashboard'!$B$8,'Cleaned Data'!$B$2:$B$34,"<="&'Sales Dashboard'!$F$8,'Cleaned Data'!$F$2:$F$34,A22) -> 3 | F22: =COUNTIFS('Cleaned Data'!$H$2:$H$34,IF('Sales Dashboard'!$B$6="All","*",'Sales Dashboard'!$B$6),'Cleaned Data'!$G$2:$G$34,IF('Sales Dashboard'!$F$6="All","*",'Sales Dashboard'!$F$6),'Cleaned Data'!$F$2:$F$34,IF('Sales Dashboard'!$J$6="All","*",'Sales Dashboard'!$J$6),'Cleaned Data'!$Q$2:$Q$34,IF('Sales Dashboard'!$N$6="All","*",'Sales Dashboard'!$N$6),'Cleaned Data'!$B$2:$B$34,">="&'Sales Dashboard'!$B$8,'Cleaned Data'!$B$2:$B$34,"<="&'Sales Dashboard'!$F$8,'Cleaned Data'!$F$2:$F$34,A22) -> 3 | G22: =SUMPRODUCT(((IF('Sales Dashboard'!$B$6="All",1,--('Cleaned Data'!$H$2:$H$34='Sales Dashboard'!$B$6))*IF('Sales Dashboard'!$F$6="All",1,--('Cleaned Data'!$G$2:$G$34='Sales Dashboard'!$F$6))*IF('Sales Dashboard'!$J$6="All",1,--('Cleaned Data'!$F$2:$F$34='Sales Dashboard'!$J$6))*IF('Sales Dashboard'!$N$6="All",1,--('Cleaned Data'!$Q$2:$Q$34='Sales Dashboard'!$N$6))*--('Cleaned Data'!$B$2:$B$34>='Sales Dashboard'!$B$8)*--('Cleaned Data'!$B$2:$B$34<='Sales Dashboard'!$F$8))*--('Cleaned Data'!$F$2:$F$34=A22))/(COUNTIFS('Cleaned Data'!$A$2:$A$34,'Cleaned Data'!$A$2:$A$34,'Cleaned Data'!$H$2:$H$34,IF('Sales Dashboard'!$B$6="All","*",'Sales Dashboard'!$B$6),'Cleaned Data'!$G$2:$G$34,IF('Sales Dashboard'!$F$6="All","*",'Sales Dashboard'!$F$6),'Cleaned Data'!$F$2:$F$34,IF('Sales Dashboard'!$J$6="All","*",'Sales Dashboard'!$J$6),'Cleaned Data'!$Q$2:$Q$34,IF('Sales Dashboard'!$N$6="All","*",'Sales Dashboard'!$N$6),'Cleaned Data'!$B$2:$B$34,">="&'Sales Dashboard'!$B$8,'Cleaned Data'!$B$2:$B$34,"<="&'Sales Dashboard'!$F$8,'Cleaned Data'!$F$2:$F$34,A22)+1-((IF('Sales Dashboard'!$B$6="All",1,--('Cleaned Data'!$H$2:$H$34='Sales Dashboard'!$B$6))*IF('Sales Dashboard'!$F$6="All",1,--('Cleaned Data'!$G$2:$G$34='Sales Dashboard'!$F$6))*IF('Sales Dashboard'!$J$6="All",1,--('Cleaned Data'!$F$2:$F$34='Sales Dashboard'!$J$6))*IF('Sales Dashboard'!$N$6="All",1,--('Cleaned Data'!$Q$2:$Q$34='Sales Dashboard'!$N$6))*--('Cleaned Data'!$B$2:$B$34>='Sales Dashboard'!$B$8)*--('Cleaned Data'!$B$2:$B$34<='Sales Dashboard'!$F$8))*--('Cleaned Data'!$F$2:$F$34=A22)))) -> 3 | H22: =IFERROR(D22/B22,0) -> 0.17213115
A23: Tablet | B23: =SUMIFS('Cleaned Data'!$K$2:$K$34,'Cleaned Data'!$H$2:$H$34,IF('Sales Dashboard'!$B$6="All","*",'Sales Dashboard'!$B$6),'Cleaned Data'!$G$2:$G$34,IF('Sales Dashboard'!$F$6="All","*",'Sales Dashboard'!$F$6),'Cleaned Data'!$F$2:$F$34,IF('Sales Dashboard'!$J$6="All","*",'Sales Dashboard'!$J$6),'Cleaned Data'!$Q$2:$Q$34,IF('Sales Dashboard'!$N$6="All","*",'Sales Dashboard'!$N$6),'Cleaned Data'!$B$2:$B$34,">="&'Sales Dashboard'!$B$8,'Cleaned Data'!$B$2:$B$34,"<="&'Sales Dashboard'!$F$8,'Cleaned Data'!$F$2:$F$34,A23) -> 92000 | C23: =SUMIFS('Cleaned Data'!$L$2:$L$34,'Cleaned Data'!$H$2:$H$34,IF('Sales Dashboard'!$B$6="All","*",'Sales Dashboard'!$B$6),'Cleaned Data'!$G$2:$G$34,IF('Sales Dashboard'!$F$6="All","*",'Sales Dashboard'!$F$6),'Cleaned Data'!$F$2:$F$34,IF('Sales Dashboard'!$J$6="All","*",'Sales Dashboard'!$J$6),'Cleaned Data'!$Q$2:$Q$34,IF('Sales Dashboard'!$N$6="All","*",'Sales Dashboard'!$N$6),'Cleaned Data'!$B$2:$B$34,">="&'Sales Dashboard'!$B$8,'Cleaned Data'!$B$2:$B$34,"<="&'Sales Dashboard'!$F$8,'Cleaned Data'!$F$2:$F$34,A23) -> 77000 | D23: =SUMIFS('Cleaned Data'!$M$2:$M$34,'Cleaned Data'!$H$2:$H$34,IF('Sales Dashboard'!$B$6="All","*",'Sales Dashboard'!$B$6),'Cleaned Data'!$G$2:$G$34,IF('Sales Dashboard'!$F$6="All","*",'Sales Dashboard'!$F$6),'Cleaned Data'!$F$2:$F$34,IF('Sales Dashboard'!$J$6="All","*",'Sales Dashboard'!$J$6),'Cleaned Data'!$Q$2:$Q$34,IF('Sales Dashboard'!$N$6="All","*",'Sales Dashboard'!$N$6),'Cleaned Data'!$B$2:$B$34,">="&'Sales Dashboard'!$B$8,'Cleaned Data'!$B$2:$B$34,"<="&'Sales Dashboard'!$F$8,'Cleaned Data'!$F$2:$F$34,A23) -> 15000 | E23: =SUMIFS('Cleaned Data'!$I$2:$I$34,'Cleaned Data'!$H$2:$H$34,IF('Sales Dashboard'!$B$6="All","*",'Sales Dashboard'!$B$6),'Cleaned Data'!$G$2:$G$34,IF('Sales Dashboard'!$F$6="All","*",'Sales Dashboard'!$F$6),'Cleaned Data'!$F$2:$F$34,IF('Sales Dashboard'!$J$6="All","*",'Sales Dashboard'!$J$6),'Cleaned Data'!$Q$2:$Q$34,IF('Sales Dashboard'!$N$6="All","*",'Sales Dashboard'!$N$6),'Cleaned Data'!$B$2:$B$34,">="&'Sales Dashboard'!$B$8,'Cleaned Data'!$B$2:$B$34,"<="&'Sales Dashboard'!$F$8,'Cleaned Data'!$F$2:$F$34,A23) -> 5 | F23: =COUNTIFS('Cleaned Data'!$H$2:$H$34,IF('Sales Dashboard'!$B$6="All","*",'Sales Dashboard'!$B$6),'Cleaned Data'!$G$2:$G$34,IF('Sales Dashboard'!$F$6="All","*",'Sales Dashboard'!$F$6),'Cleaned Data'!$F$2:$F$34,IF('Sales Dashboard'!$J$6="All","*",'Sales Dashboard'!$J$6),'Cleaned Data'!$Q$2:$Q$34,IF('Sales Dashboard'!$N$6="All","*",'Sales Dashboard'!$N$6),'Cleaned Data'!$B$2:$B$34,">="&'Sales Dashboard'!$B$8,'Cleaned Data'!$B$2:$B$34,"<="&'Sales Dashboard'!$F$8,'Cleaned Data'!$F$2:$F$34,A23) -> 2 | G23: =SUMPRODUCT(((IF('Sales Dashboard'!$B$6="All",1,--('Cleaned Data'!$H$2:$H$34='Sales Dashboard'!$B$6))*IF('Sales Dashboard'!$F$6="All",1,--('Cleaned Data'!$G$2:$G$34='Sales Dashboard'!$F$6))*IF('Sales Dashboard'!$J$6="All",1,--('Cleaned Data'!$F$2:$F$34='Sales Dashboard'!$J$6))*IF('Sales Dashboard'!$N$6="All",1,--('Cleaned Data'!$Q$2:$Q$34='Sales Dashboard'!$N$6))*--('Cleaned Data'!$B$2:$B$34>='Sales Dashboard'!$B$8)*--('Cleaned Data'!$B$2:$B$34<='Sales Dashboard'!$F$8))*--('Cleaned Data'!$F$2:$F$34=A23))/(COUNTIFS('Cleaned Data'!$A$2:$A$34,'Cleaned Data'!$A$2:$A$34,'Cleaned Data'!$H$2:$H$34,IF('Sales Dashboard'!$B$6="All","*",'Sales Dashboard'!$B$6),'Cleaned Data'!$G$2:$G$34,IF('Sales Dashboard'!$F$6="All","*",'Sales Dashboard'!$F$6),'Cleaned Data'!$F$2:$F$34,IF('Sales Dashboard'!$J$6="All","*",'Sales Dashboard'!$J$6),'Cleaned Data'!$Q$2:$Q$34,IF('Sales Dashboard'!$N$6="All","*",'Sales Dashboard'!$N$6),'Cleaned Data'!$B$2:$B$34,">="&'Sales Dashboard'!$B$8,'Cleaned Data'!$B$2:$B$34,"<="&'Sales Dashboard'!$F$8,'Cleaned Data'!$F$2:$F$34,A23)+1-((IF('Sales Dashboard'!$B$6="All",1,--('Cleaned Data'!$H$2:$H$34='Sales Dashboard'!$B$6))*IF('Sales Dashboard'!$F$6="All",1,--('Cleaned Data'!$G$2:$G$34='Sales Dashboard'!$F$6))*IF('Sales Dashboard'!$J$6="All",1,--('Cleaned Data'!$F$2:$F$34='Sales Dashboard'!$J$6))*IF('Sales Dashboard'!$N$6="All",1,--('Cleaned Data'!$Q$2:$Q$34='Sales Dashboard'!$N$6))*--('Cleaned Data'!$B$2:$B$34>='Sales Dashboard'!$B$8)*--('Cleaned Data'!$B$2:$B$34<='Sales Dashboard'!$F$8))*--('Cleaned Data'!$F$2:$F$34=A23)))) -> 2 | H23: =IFERROR(D23/B23,0) -> 0.16304348
A24: Monitor | B24: =SUMIFS('Cleaned Data'!$K$2:$K$34,'Cleaned Data'!$H$2:$H$34,IF('Sales Dashboard'!$B$6="All","*",'Sales Dashboard'!$B$6),'Cleaned Data'!$G$2:$G$34,IF('Sales Dashboard'!$F$6="All","*",'Sales Dashboard'!$F$6),'Cleaned Data'!$F$2:$F$34,IF('Sales Dashboard'!$J$6="All","*",'Sales Dashboard'!$J$6),'Cleaned Data'!$Q$2:$Q$34,IF('Sales Dashboard'!$N$6="All","*",'Sales Dashboard'!$N$6),'Cleaned Data'!$B$2:$B$34,">="&'Sales Dashboard'!$B$8,'Cleaned Data'!$B$2:$B$34,"<="&'Sales Dashboard'!$F$8,'Cleaned Data'!$F$2:$F$34,A24) -> 72000 | C24: =SUMIFS('Cleaned Data'!$L$2:$L$34,'Cleaned Data'!$H$2:$H$34,IF('Sales Dashboard'!$B$6="All","*",'Sales Dashboard'!$B$6),'Cleaned Data'!$G$2:$G$34,IF('Sales Dashboard'!$F$6="All","*",'Sales Dashboard'!$F$6),'Cleaned Data'!$F$2:$F$34,IF('Sales Dashboard'!$J$6="All","*",'Sales Dashboard'!$J$6),'Cleaned Data'!$Q$2:$Q$34,IF('Sales Dashboard'!$N$6="All","*",'Sales Dashboard'!$N$6),'Cleaned Data'!$B$2:$B$34,">="&'Sales Dashboard'!$B$8,'Cleaned Data'!$B$2:$B$34,"<="&'Sales Dashboard'!$F$8,'Cleaned Data'!$F$2:$F$34,A24) -> 60000 | D24: =SUMIFS('Cleaned Data'!$M$2:$M$34,'Cleaned Data'!$H$2:$H$34,IF('Sales Dashboard'!$B$6="All","*",'Sales Dashboard'!$B$6),'Cleaned Data'!$G$2:$G$34,IF('Sales Dashboard'!$F$6="All","*",'Sales Dashboard'!$F$6),'Cleaned Data'!$F$2:$F$34,IF('Sales Dashboard'!$J$6="All","*",'Sales Dashboard'!$J$6),'Cleaned Data'!$Q$2:$Q$34,IF('Sales Dashboard'!$N$6="All","*",'Sales Dashboard'!$N$6),'Cleaned Data'!$B$2:$B$34,">="&'Sales Dashboard'!$B$8,'Cleaned Data'!$B$2:$B$34,"<="&'Sales Dashboard'!$F$8,'Cleaned Data'!$F$2:$F$34,A24) -> 12000 | E24: =SUMIFS('Cleaned Data'!$I$2:$I$34,'Cleaned Data'!$H$2:$H$34,IF('Sales Dashboard'!$B$6="All","*",'Sales Dashboard'!$B$6),'Cleaned Data'!$G$2:$G$34,IF('Sales Dashboard'!$F$6="All","*",'Sales Dashboard'!$F$6),'Cleaned Data'!$F$2:$F$34,IF('Sales Dashboard'!$J$6="All","*",'Sales Dashboard'!$J$6),'Cleaned Data'!$Q$2:$Q$34,IF('Sales Dashboard'!$N$6="All","*",'Sales Dashboard'!$N$6),'Cleaned Data'!$B$2:$B$34,">="&'Sales Dashboard'!$B$8,'Cleaned Data'!$B$2:$B$34,"<="&'Sales Dashboard'!$F$8,'Cleaned Data'!$F$2:$F$34,A24) -> 5 | F24: =COUNTIFS('Cleaned Data'!$H$2:$H$34,IF('Sales Dashboard'!$B$6="All","*",'Sales Dashboard'!$B$6),'Cleaned Data'!$G$2:$G$34,IF('Sales Dashboard'!$F$6="All","*",'Sales Dashboard'!$F$6),'Cleaned Data'!$F$2:$F$34,IF('Sales Dashboard'!$J$6="All","*",'Sales Dashboard'!$J$6),'Cleaned Data'!$Q$2:$Q$34,IF('Sales Dashboard'!$N$6="All","*",'Sales Dashboard'!$N$6),'Cleaned Data'!$B$2:$B$34,">="&'Sales Dashboard'!$B$8,'Cleaned Data'!$B$2:$B$34,"<="&'Sales Dashboard'!$F$8,'Cleaned Data'!$F$2:$F$34,A24) -> 2 | G24: =SUMPRODUCT(((IF('Sales Dashboard'!$B$6="All",1,--('Cleaned Data'!$H$2:$H$34='Sales Dashboard'!$B$6))*IF('Sales Dashboard'!$F$6="All",1,--('Cleaned Data'!$G$2:$G$34='Sales Dashboard'!$F$6))*IF('Sales Dashboard'!$J$6="All",1,--('Cleaned Data'!$F$2:$F$34='Sales Dashboard'!$J$6))*IF('Sales Dashboard'!$N$6="All",1,--('Cleaned Data'!$Q$2:$Q$34='Sales Dashboard'!$N$6))*--('Cleaned Data'!$B$2:$B$34>='Sales Dashboard'!$B$8)*--('Cleaned Data'!$B$2:$B$34<='Sales Dashboard'!$F$8))*--('Cleaned Data'!$F$2:$F$34=A24))/(COUNTIFS('Cleaned Data'!$A$2:$A$34,'Cleaned Data'!$A$2:$A$34,'Cleaned Data'!$H$2:$H$34,IF('Sales Dashboard'!$B$6="All","*",'Sales Dashboard'!$B$6),'Cleaned Data'!$G$2:$G$34,IF('Sales Dashboard'!$F$6="All","*",'Sales Dashboard'!$F$6),'Cleaned Data'!$F$2:$F$34,IF('Sales Dashboard'!$J$6="All","*",'Sales Dashboard'!$J$6),'Cleaned Data'!$Q$2:$Q$34,IF('Sales Dashboard'!$N$6="All","*",'Sales Dashboard'!$N$6),'Cleaned Data'!$B$2:$B$34,">="&'Sales Dashboard'!$B$8,'Cleaned Data'!$B$2:$B$34,"<="&'Sales Dashboard'!$F$8,'Cleaned Data'!$F$2:$F$34,A24)+1-((IF('Sales Dashboard'!$B$6="All",1,--('Cleaned Data'!$H$2:$H$34='Sales Dashboard'!$B$6))*IF('Sales Dashboard'!$F$6="All",1,--('Cleaned Data'!$G$2:$G$34='Sales Dashboard'!$F$6))*IF('Sales Dashboard'!$J$6="All",1,--('Cleaned Data'!$F$2:$F$34='Sales Dashboard'!$J$6))*IF('Sales Dashboard'!$N$6="All",1,--('Cleaned Data'!$Q$2:$Q$34='Sales Dashboard'!$N$6))*--('Cleaned Data'!$B$2:$B$34>='Sales Dashboard'!$B$8)*--('Cleaned Data'!$B$2:$B$34<='Sales Dashboard'!$F$8))*--('Cleaned Data'!$F$2:$F$34=A24)))) -> 2 | H24: =IFERROR(D24/B24,0) -> 0.16666667
A25: Chair | B25: =SUMIFS('Cleaned Data'!$K$2:$K$34,'Cleaned Data'!$H$2:$H$34,IF('Sales Dashboard'!$B$6="All","*",'Sales Dashboard'!$B$6),'Cleaned Data'!$G$2:$G$34,IF('Sales Dashboard'!$F$6="All","*",'Sales Dashboard'!$F$6),'Cleaned Data'!$F$2:$F$34,IF('Sales Dashboard'!$J$6="All","*",'Sales Dashboard'!$J$6),'Cleaned Data'!$Q$2:$Q$34,IF('Sales Dashboard'!$N$6="All","*",'Sales Dashboard'!$N$6),'Cleaned Data'!$B$2:$B$34,">="&'Sales Dashboard'!$B$8,'Cleaned Data'!$B$2:$B$34,"<="&'Sales Dashboard'!$F$8,'Cleaned Data'!$F$2:$F$34,A25) -> 68000 | C25: =SUMIFS('Cleaned Data'!$L$2:$L$34,'Cleaned Data'!$H$2:$H$34,IF('Sales Dashboard'!$B$6="All","*",'Sales Dashboard'!$B$6),'Cleaned Data'!$G$2:$G$34,IF('Sales Dashboard'!$F$6="All","*",'Sales Dashboard'!$F$6),'Cleaned Data'!$F$2:$F$34,IF('Sales Dashboard'!$J$6="All","*",'Sales Dashboard'!$J$6),'Cleaned Data'!$Q$2:$Q$34,IF('Sales Dashboard'!$N$6="All","*",'Sales Dashboard'!$N$6),'Cleaned Data'!$B$2:$B$34,">="&'Sales Dashboard'!$B$8,'Cleaned Data'!$B$2:$B$34,"<="&'Sales Dashboard'!$F$8,'Cleaned Data'!$F$2:$F$34,A25) -> 49000 | D25: =SUMIFS('Cleaned Data'!$M$2:$M$34,'Cleaned Data'!$H$2:$H$34,IF('Sales Dashboard'!$B$6="All","*",'Sales Dashboard'!$B$6),'Cleaned Data'!$G$2:$G$34,IF('Sales Dashboard'!$F$6="All","*",'Sales Dashboard'!$F$6),'Cleaned Data'!$F$2:$F$34,IF('Sales Dashboard'!$J$6="All","*",'Sales Dashboard'!$J$6),'Cleaned Data'!$Q$2:$Q$34,IF('Sales Dashboard'!$N$6="All","*",'Sales Dashboard'!$N$6),'Cleaned Data'!$B$2:$B$34,">="&'Sales Dashboard'!$B$8,'Cleaned Data'!$B$2:$B$34,"<="&'Sales Dashboard'!$F$8,'Cleaned Data'!$F$2:$F$34,A25) -> 19000 | E25: =SUMIFS('Cleaned Data'!$I$2:$I$34,'Cleaned Data'!$H$2:$H$34,IF('Sales Dashboard'!$B$6="All","*",'Sales Dashboard'!$B$6),'Cleaned Data'!$G$2:$G$34,IF('Sales Dashboard'!$F$6="All","*",'Sales Dashboard'!$F$6),'Cleaned Data'!$F$2:$F$34,IF('Sales Dashboard'!$J$6="All","*",'Sales Dashboard'!$J$6),'Cleaned Data'!$Q$2:$Q$34,IF('Sales Dashboard'!$N$6="All","*",'Sales Dashboard'!$N$6),'Cleaned Data'!$B$2:$B$34,">="&'Sales Dashboard'!$B$8,'Cleaned Data'!$B$2:$B$34,"<="&'Sales Dashboard'!$F$8,'Cleaned Data'!$F$2:$F$34,A25) -> 17 | F25: =COUNTIFS('Cleaned Data'!$H$2:$H$34,IF('Sales Dashboard'!$B$6="All","*",'Sales Dashboard'!$B$6),'Cleaned Data'!$G$2:$G$34,IF('Sales Dashboard'!$F$6="All","*",'Sales Dashboard'!$F$6),'Cleaned Data'!$F$2:$F$34,IF('Sales Dashboard'!$J$6="All","*",'Sales Dashboard'!$J$6),'Cleaned Data'!$Q$2:$Q$34,IF('Sales Dashboard'!$N$6="All","*",'Sales Dashboard'!$N$6),'Cleaned Data'!$B$2:$B$34,">="&'Sales Dashboard'!$B$8,'Cleaned Data'!$B$2:$B$34,"<="&'Sales Dashboard'!$F$8,'Cleaned Data'!$F$2:$F$34,A25) -> 4 | G25: =SUMPRODUCT(((IF('Sales Dashboard'!$B$6="All",1,--('Cleaned Data'!$H$2:$H$34='Sales Dashboard'!$B$6))*IF('Sales Dashboard'!$F$6="All",1,--('Cleaned Data'!$G$2:$G$34='Sales Dashboard'!$F$6))*IF('Sales Dashboard'!$J$6="All",1,--('Cleaned Data'!$F$2:$F$34='Sales Dashboard'!$J$6))*IF('Sales Dashboard'!$N$6="All",1,--('Cleaned Data'!$Q$2:$Q$34='Sales Dashboard'!$N$6))*--('Cleaned Data'!$B$2:$B$34>='Sales Dashboard'!$B$8)*--('Cleaned Data'!$B$2:$B$34<='Sales Dashboard'!$F$8))*--('Cleaned Data'!$F$2:$F$34=A25))/(COUNTIFS('Cleaned Data'!$A$2:$A$34,'Cleaned Data'!$A$2:$A$34,'Cleaned Data'!$H$2:$H$34,IF('Sales Dashboard'!$B$6="All","*",'Sales Dashboard'!$B$6),'Cleaned Data'!$G$2:$G$34,IF('Sales Dashboard'!$F$6="All","*",'Sales Dashboard'!$F$6),'Cleaned Data'!$F$2:$F$34,IF('Sales Dashboard'!$J$6="All","*",'Sales Dashboard'!$J$6),'Cleaned Data'!$Q$2:$Q$34,IF('Sales Dashboard'!$N$6="All","*",'Sales Dashboard'!$N$6),'Cleaned Data'!$B$2:$B$34,">="&'Sales Dashboard'!$B$8,'Cleaned Data'!$B$2:$B$34,"<="&'Sales Dashboard'!$F$8,'Cleaned Data'!$F$2:$F$34,A25)+1-((IF('Sales Dashboard'!$B$6="All",1,--('Cleaned Data'!$H$2:$H$34='Sales Dashboard'!$B$6))*IF('Sales Dashboard'!$F$6="All",1,--('Cleaned Data'!$G$2:$G$34='Sales Dashboard'!$F$6))*IF('Sales Dashboard'!$J$6="All",1,--('Cleaned Data'!$F$2:$F$34='Sales Dashboard'!$J$6))*IF('Sales Dashboard'!$N$6="All",1,--('Cleaned Data'!$Q$2:$Q$34='Sales Dashboard'!$N$6))*--('Cleaned Data'!$B$2:$B$34>='Sales Dashboard'!$B$8)*--('Cleaned Data'!$B$2:$B$34<='Sales Dashboard'!$F$8))*--('Cleaned Data'!$F$2:$F$34=A25)))) -> 3 | H25: =IFERROR(D25/B25,0) -> 0.27941176
A26: Table | B26: =SUMIFS('Cleaned Data'!$K$2:$K$34,'Cleaned Data'!$H$2:$H$34,IF('Sales Dashboard'!$B$6="All","*",'Sales Dashboard'!$B$6),'Cleaned Data'!$G$2:$G$34,IF('Sales Dashboard'!$F$6="All","*",'Sales Dashboard'!$F$6),'Cleaned Data'!$F$2:$F$34,IF('Sales Dashboard'!$J$6="All","*",'Sales Dashboard'!$J$6),'Cleaned Data'!$Q$2:$Q$34,IF('Sales Dashboard'!$N$6="All","*",'Sales Dashboard'!$N$6),'Cleaned Data'!$B$2:$B$34,">="&'Sales Dashboard'!$B$8,'Cleaned Data'!$B$2:$B$34,"<="&'Sales Dashboard'!$F$8,'Cleaned Data'!$F$2:$F$34,A26) -> 46000 | C26: =SUMIFS('Cleaned Data'!$L$2:$L$34,'Cleaned Data'!$H$2:$H$34,IF('Sales Dashboard'!$B$6="All","*",'Sales Dashboard'!$B$6),'Cleaned Data'!$G$2:$G$34,IF('Sales Dashboard'!$F$6="All","*",'Sales Dashboard'!$F$6),'Cleaned Data'!$F$2:$F$34,IF('Sales Dashboard'!$J$6="All","*",'Sales Dashboard'!$J$6),'Cleaned Data'!$Q$2:$Q$34,IF('Sales Dashboard'!$N$6="All","*",'Sales Dashboard'!$N$6),'Cleaned Data'!$B$2:$B$34,">="&'Sales Dashboard'!$B$8,'Cleaned Data'!$B$2:$B$34,"<="&'Sales Dashboard'!$F$8,'Cleaned Data'!$F$2:$F$34,A26) -> 39000 | D26: =SUMIFS('Cleaned Data'!$M$2:$M$34,'Cleaned Data'!$H$2:$H$34,IF('Sales Dashboard'!$B$6="All","*",'Sales Dashboard'!$B$6),'Cleaned Data'!$G$2:$G$34,IF('Sales Dashboard'!$F$6="All","*",'Sales Dashboard'!$F$6),'Cleaned Data'!$F$2:$F$34,IF('Sales Dashboard'!$J$6="All","*",'Sales Dashboard'!$J$6),'Cleaned Data'!$Q$2:$Q$34,IF('Sales Dashboard'!$N$6="All","*",'Sales Dashboard'!$N$6),'Cleaned Data'!$B$2:$B$34,">="&'Sales Dashboard'!$B$8,'Cleaned Data'!$B$2:$B$34,"<="&'Sales Dashboard'!$F$8,'Cleaned Data'!$F$2:$F$34,A26) -> 7000 | E26: =SUMIFS('Cleaned Data'!$I$2:$I$34,'Cleaned Data'!$H$2:$H$34,IF('Sales Dashboard'!$B$6="All","*",'Sales Dashboard'!$B$6),'Cleaned Data'!$G$2:$G$34,IF('Sales Dashboard'!$F$6="All","*",'Sales Dashboard'!$F$6),'Cleaned Data'!$F$2:$F$34,IF('Sales Dashboard'!$J$6="All","*",'Sales Dashboard'!$J$6),'Cleaned Data'!$Q$2:$Q$34,IF('Sales Dashboard'!$N$6="All","*",'Sales Dashboard'!$N$6),'Cleaned Data'!$B$2:$B$34,">="&'Sales Dashboard'!$B$8,'Cleaned Data'!$B$2:$B$34,"<="&'Sales Dashboard'!$F$8,'Cleaned Data'!$F$2:$F$34,A26) -> 6 | F26: =COUNTIFS('Cleaned Data'!$H$2:$H$34,IF('Sales Dashboard'!$B$6="All","*",'Sales Dashboard'!$B$6),'Cleaned Data'!$G$2:$G$34,IF('Sales Dashboard'!$F$6="All","*",'Sales Dashboard'!$F$6),'Cleaned Data'!$F$2:$F$34,IF('Sales Dashboard'!$J$6="All","*",'Sales Dashboard'!$J$6),'Cleaned Data'!$Q$2:$Q$34,IF('Sales Dashboard'!$N$6="All","*",'Sales Dashboard'!$N$6),'Cleaned Data'!$B$2:$B$34,">="&'Sales Dashboard'!$B$8,'Cleaned Data'!$B$2:$B$34,"<="&'Sales Dashboard'!$F$8,'Cleaned Data'!$F$2:$F$34,A26) -> 3 | G26: =SUMPRODUCT(((IF('Sales Dashboard'!$B$6="All",1,--('Cleaned Data'!$H$2:$H$34='Sales Dashboard'!$B$6))*IF('Sales Dashboard'!$F$6="All",1,--('Cleaned Data'!$G$2:$G$34='Sales Dashboard'!$F$6))*IF('Sales Dashboard'!$J$6="All",1,--('Cleaned Data'!$F$2:$F$34='Sales Dashboard'!$J$6))*IF('Sales Dashboard'!$N$6="All",1,--('Cleaned Data'!$Q$2:$Q$34='Sales Dashboard'!$N$6))*--('Cleaned Data'!$B$2:$B$34>='Sales Dashboard'!$B$8)*--('Cleaned Data'!$B$2:$B$34<='Sales Dashboard'!$F$8))*--('Cleaned Data'!$F$2:$F$34=A26))/(COUNTIFS('Cleaned Data'!$A$2:$A$34,'Cleaned Data'!$A$2:$A$34,'Cleaned Data'!$H$2:$H$34,IF('Sales Dashboard'!$B$6="All","*",'Sales Dashboard'!$B$6),'Cleaned Data'!$G$2:$G$34,IF('Sales Dashboard'!$F$6="All","*",'Sales Dashboard'!$F$6),'Cleaned Data'!$F$2:$F$34,IF('Sales Dashboard'!$J$6="All","*",'Sales Dashboard'!$J$6),'Cleaned Data'!$Q$2:$Q$34,IF('Sales Dashboard'!$N$6="All","*",'Sales Dashboard'!$N$6),'Cleaned Data'!$B$2:$B$34,">="&'Sales Dashboard'!$B$8,'Cleaned Data'!$B$2:$B$34,"<="&'Sales Dashboard'!$F$8,'Cleaned Data'!$F$2:$F$34,A26)+1-((IF('Sales Dashboard'!$B$6="All",1,--('Cleaned Data'!$H$2:$H$34='Sales Dashboard'!$B$6))*IF('Sales Dashboard'!$F$6="All",1,--('Cleaned Data'!$G$2:$G$34='Sales Dashboard'!$F$6))*IF('Sales Dashboard'!$J$6="All",1,--('Cleaned Data'!$F$2:$F$34='Sales Dashboard'!$J$6))*IF('Sales Dashboard'!$N$6="All",1,--('Cleaned Data'!$Q$2:$Q$34='Sales Dashboard'!$N$6))*--('Cleaned Data'!$B$2:$B$34>='Sales Dashboard'!$B$8)*--('Cleaned Data'!$B$2:$B$34<='Sales Dashboard'!$F$8))*--('Cleaned Data'!$F$2:$F$34=A26)))) -> 2 | H26: =IFERROR(D26/B26,0) -> 0.15217391
A27: Printer | B27: =SUMIFS('Cleaned Data'!$K$2:$K$34,'Cleaned Data'!$H$2:$H$34,IF('Sales Dashboard'!$B$6="All","*",'Sales Dashboard'!$B$6),'Cleaned Data'!$G$2:$G$34,IF('Sales Dashboard'!$F$6="All","*",'Sales Dashboard'!$F$6),'Cleaned Data'!$F$2:$F$34,IF('Sales Dashboard'!$J$6="All","*",'Sales Dashboard'!$J$6),'Cleaned Data'!$Q$2:$Q$34,IF('Sales Dashboard'!$N$6="All","*",'Sales Dashboard'!$N$6),'Cleaned Data'!$B$2:$B$34,">="&'Sales Dashboard'!$B$8,'Cleaned Data'!$B$2:$B$34,"<="&'Sales Dashboard'!$F$8,'Cleaned Data'!$F$2:$F$34,A27) -> 34000 | C27: =SUMIFS('Cleaned Data'!$L$2:$L$34,'Cleaned Data'!$H$2:$H$34,IF('Sales Dashboard'!$B$6="All","*",'Sales Dashboard'!$B$6),'Cleaned Data'!$G$2:$G$34,IF('Sales Dashboard'!$F$6="All","*",'Sales Dashboard'!$F$6),'Cleaned Data'!$F$2:$F$34,IF('Sales Dashboard'!$J$6="All","*",'Sales Dashboard'!$J$6),'Cleaned Data'!$Q$2:$Q$34,IF('Sales Dashboard'!$N$6="All","*",'Sales Dashboard'!$N$6),'Cleaned Data'!$B$2:$B$34,">="&'Sales Dashboard'!$B$8,'Cleaned Data'!$B$2:$B$34,"<="&'Sales Dashboard'!$F$8,'Cleaned Data'!$F$2:$F$34,A27) -> 26000 | D27: =SUMIFS('Cleaned Data'!$M$2:$M$34,'Cleaned Data'!$H$2:$H$34,IF('Sales Dashboard'!$B$6="All","*",'Sales Dashboard'!$B$6),'Cleaned Data'!$G$2:$G$34,IF('Sales Dashboard'!$F$6="All","*",'Sales Dashboard'!$F$6),'Cleaned Data'!$F$2:$F$34,IF('Sales Dashboard'!$J$6="All","*",'Sales Dashboard'!$J$6),'Cleaned Data'!$Q$2:$Q$34,IF('Sales Dashboard'!$N$6="All","*",'Sales Dashboard'!$N$6),'Cleaned Data'!$B$2:$B$34,">="&'Sales Dashboard'!$B$8,'Cleaned Data'!$B$2:$B$34,"<="&'Sales Dashboard'!$F$8,'Cleaned Data'!$F$2:$F$34,A27) -> 8000 | E27: =SUMIFS('Cleaned Data'!$I$2:$I$34,'Cleaned Data'!$H$2:$H$34,IF('Sales Dashboard'!$B$6="All","*",'Sales Dashboard'!$B$6),'Cleaned Data'!$G$2:$G$34,IF('Sales Dashboard'!$F$6="All","*",'Sales Dashboard'!$F$6),'Cleaned Data'!$F$2:$F$34,IF('Sales Dashboard'!$J$6="All","*",'Sales Dashboard'!$J$6),'Cleaned Data'!$Q$2:$Q$34,IF('Sales Dashboard'!$N$6="All","*",'Sales Dashboard'!$N$6),'Cleaned Data'!$B$2:$B$34,">="&'Sales Dashboard'!$B$8,'Cleaned Data'!$B$2:$B$34,"<="&'Sales Dashboard'!$F$8,'Cleaned Data'!$F$2:$F$34,A27) -> 3 | F27: =COUNTIFS('Cleaned Data'!$H$2:$H$34,IF('Sales Dashboard'!$B$6="All","*",'Sales Dashboard'!$B$6),'Cleaned Data'!$G$2:$G$34,IF('Sales Dashboard'!$F$6="All","*",'Sales Dashboard'!$F$6),'Cleaned Data'!$F$2:$F$34,IF('Sales Dashboard'!$J$6="All","*",'Sales Dashboard'!$J$6),'Cleaned Data'!$Q$2:$Q$34,IF('Sales Dashboard'!$N$6="All","*",'Sales Dashboard'!$N$6),'Cleaned Data'!$B$2:$B$34,">="&'Sales Dashboard'!$B$8,'Cleaned Data'!$B$2:$B$34,"<="&'Sales Dashboard'!$F$8,'Cleaned Data'!$F$2:$F$34,A27) -> 2 | G27: =SUMPRODUCT(((IF('Sales Dashboard'!$B$6="All",1,--('Cleaned Data'!$H$2:$H$34='Sales Dashboard'!$B$6))*IF('Sales Dashboard'!$F$6="All",1,--('Cleaned Data'!$G$2:$G$34='Sales Dashboard'!$F$6))*IF('Sales Dashboard'!$J$6="All",1,--('Cleaned Data'!$F$2:$F$34='Sales Dashboard'!$J$6))*IF('Sales Dashboard'!$N$6="All",1,--('Cleaned Data'!$Q$2:$Q$34='Sales Dashboard'!$N$6))*--('Cleaned Data'!$B$2:$B$34>='Sales Dashboard'!$B$8)*--('Cleaned Data'!$B$2:$B$34<='Sales Dashboard'!$F$8))*--('Cleaned Data'!$F$2:$F$34=A27))/(COUNTIFS('Cleaned Data'!$A$2:$A$34,'Cleaned Data'!$A$2:$A$34,'Cleaned Data'!$H$2:$H$34,IF('Sales Dashboard'!$B$6="All","*",'Sales Dashboard'!$B$6),'Cleaned Data'!$G$2:$G$34,IF('Sales Dashboard'!$F$6="All","*",'Sales Dashboard'!$F$6),'Cleaned Data'!$F$2:$F$34,IF('Sales Dashboard'!$J$6="All","*",'Sales Dashboard'!$J$6),'Cleaned Data'!$Q$2:$Q$34,IF('Sales Dashboard'!$N$6="All","*",'Sales Dashboard'!$N$6),'Cleaned Data'!$B$2:$B$34,">="&'Sales Dashboard'!$B$8,'Cleaned Data'!$B$2:$B$34,"<="&'Sales Dashboard'!$F$8,'Cleaned Data'!$F$2:$F$34,A27)+1-((IF('Sales Dashboard'!$B$6="All",1,--('Cleaned Data'!$H$2:$H$34='Sales Dashboard'!$B$6))*IF('Sales Dashboard'!$F$6="All",1,--('Cleaned Data'!$G$2:$G$34='Sales Dashboard'!$F$6))*IF('Sales Dashboard'!$J$6="All",1,--('Cleaned Data'!$F$2:$F$34='Sales Dashboard'!$J$6))*IF('Sales Dashboard'!$N$6="All",1,--('Cleaned Data'!$Q$2:$Q$34='Sales Dashboard'!$N$6))*--('Cleaned Data'!$B$2:$B$34>='Sales Dashboard'!$B$8)*--('Cleaned Data'!$B$2:$B$34<='Sales Dashboard'!$F$8))*--('Cleaned Data'!$F$2:$F$34=A27)))) -> 2 | H27: =IFERROR(D27/B27,0) -> 0.23529412
A28: Bookshelf | B28: =SUMIFS('Cleaned Data'!$K$2:$K$34,'Cleaned Data'!$H$2:$H$34,IF('Sales Dashboard'!$B$6="All","*",'Sales Dashboard'!$B$6),'Cleaned Data'!$G$2:$G$34,IF('Sales Dashboard'!$F$6="All","*",'Sales Dashboard'!$F$6),'Cleaned Data'!$F$2:$F$34,IF('Sales Dashboard'!$J$6="All","*",'Sales Dashboard'!$J$6),'Cleaned Data'!$Q$2:$Q$34,IF('Sales Dashboard'!$N$6="All","*",'Sales Dashboard'!$N$6),'Cleaned Data'!$B$2:$B$34,">="&'Sales Dashboard'!$B$8,'Cleaned Data'!$B$2:$B$34,"<="&'Sales Dashboard'!$F$8,'Cleaned Data'!$F$2:$F$34,A28) -> 28000 | C28: =SUMIFS('Cleaned Data'!$L$2:$L$34,'Cleaned Data'!$H$2:$H$34,IF('Sales Dashboard'!$B$6="All","*",'Sales Dashboard'!$B$6),'Cleaned Data'!$G$2:$G$34,IF('Sales Dashboard'!$F$6="All","*",'Sales Dashboard'!$F$6),'Cleaned Data'!$F$2:$F$34,IF('Sales Dashboard'!$J$6="All","*",'Sales Dashboard'!$J$6),'Cleaned Data'!$Q$2:$Q$34,IF('Sales Dashboard'!$N$6="All","*",'Sales Dashboard'!$N$6),'Cleaned Data'!$B$2:$B$34,">="&'Sales Dashboard'!$B$8,'Cleaned Data'!$B$2:$B$34,"<="&'Sales Dashboard'!$F$8,'Cleaned Data'!$F$2:$F$34,A28) -> 19000 | D28: =SUMIFS('Cleaned Data'!$M$2:$M$34,'Cleaned Data'!$H$2:$H$34,IF('Sales Dashboard'!$B$6="All","*",'Sales Dashboard'!$B$6),'Cleaned Data'!$G$2:$G$34,IF('Sales Dashboard'!$F$6="All","*",'Sales Dashboard'!$F$6),'Cleaned Data'!$F$2:$F$34,IF('Sales Dashboard'!$J$6="All","*",'Sales Dashboard'!$J$6),'Cleaned Data'!$Q$2:$Q$34,IF('Sales Dashboard'!$N$6="All","*",'Sales Dashboard'!$N$6),'Cleaned Data'!$B$2:$B$34,">="&'Sales Dashboard'!$B$8,'Cleaned Data'!$B$2:$B$34,"<="&'Sales Dashboard'!$F$8,'Cleaned Data'!$F$2:$F$34,A28) -> 9000 | E28: =SUMIFS('Cleaned Data'!$I$2:$I$34,'Cleaned Data'!$H$2:$H$34,IF('Sales Dashboard'!$B$6="All","*",'Sales Dashboard'!$B$6),'Cleaned Data'!$G$2:$G$34,IF('Sales Dashboard'!$F$6="All","*",'Sales Dashboard'!$F$6),'Cleaned Data'!$F$2:$F$34,IF('Sales Dashboard'!$J$6="All","*",'Sales Dashboard'!$J$6),'Cleaned Data'!$Q$2:$Q$34,IF('Sales Dashboard'!$N$6="All","*",'Sales Dashboard'!$N$6),'Cleaned Data'!$B$2:$B$34,">="&'Sales Dashboard'!$B$8,'Cleaned Data'!$B$2:$B$34,"<="&'Sales Dashboard'!$F$8,'Cleaned Data'!$F$2:$F$34,A28) -> 4 | F28: =COUNTIFS('Cleaned Data'!$H$2:$H$34,IF('Sales Dashboard'!$B$6="All","*",'Sales Dashboard'!$B$6),'Cleaned Data'!$G$2:$G$34,IF('Sales Dashboard'!$F$6="All","*",'Sales Dashboard'!$F$6),'Cleaned Data'!$F$2:$F$34,IF('Sales Dashboard'!$J$6="All","*",'Sales Dashboard'!$J$6),'Cleaned Data'!$Q$2:$Q$34,IF('Sales Dashboard'!$N$6="All","*",'Sales Dashboard'!$N$6),'Cleaned Data'!$B$2:$B$34,">="&'Sales Dashboard'!$B$8,'Cleaned Data'!$B$2:$B$34,"<="&'Sales Dashboard'!$F$8,'Cleaned Data'!$F$2:$F$34,A28) -> 2 | G28: =SUMPRODUCT(((IF('Sales Dashboard'!$B$6="All",1,--('Cleaned Data'!$H$2:$H$34='Sales Dashboard'!$B$6))*IF('Sales Dashboard'!$F$6="All",1,--('Cleaned Data'!$G$2:$G$34='Sales Dashboard'!$F$6))*IF('Sales Dashboard'!$J$6="All",1,--('Cleaned Data'!$F$2:$F$34='Sales Dashboard'!$J$6))*IF('Sales Dashboard'!$N$6="All",1,--('Cleaned Data'!$Q$2:$Q$34='Sales Dashboard'!$N$6))*--('Cleaned Data'!$B$2:$B$34>='Sales Dashboard'!$B$8)*--('Cleaned Data'!$B$2:$B$34<='Sales Dashboard'!$F$8))*--('Cleaned Data'!$F$2:$F$34=A28))/(COUNTIFS('Cleaned Data'!$A$2:$A$34,'Cleaned Data'!$A$2:$A$34,'Cleaned Data'!$H$2:$H$34,IF('Sales Dashboard'!$B$6="All","*",'Sales Dashboard'!$B$6),'Cleaned Data'!$G$2:$G$34,IF('Sales Dashboard'!$F$6="All","*",'Sales Dashboard'!$F$6),'Cleaned Data'!$F$2:$F$34,IF('Sales Dashboard'!$J$6="All","*",'Sales Dashboard'!$J$6),'Cleaned Data'!$Q$2:$Q$34,IF('Sales Dashboard'!$N$6="All","*",'Sales Dashboard'!$N$6),'Cleaned Data'!$B$2:$B$34,">="&'Sales Dashboard'!$B$8,'Cleaned Data'!$B$2:$B$34,"<="&'Sales Dashboard'!$F$8,'Cleaned Data'!$F$2:$F$34,A28)+1-((IF('Sales Dashboard'!$B$6="All",1,--('Cleaned Data'!$H$2:$H$34='Sales Dashboard'!$B$6))*IF('Sales Dashboard'!$F$6="All",1,--('Cleaned Data'!$G$2:$G$34='Sales Dashboard'!$F$6))*IF('Sales Dashboard'!$J$6="All",1,--('Cleaned Data'!$F$2:$F$34='Sales Dashboard'!$J$6))*IF('Sales Dashboard'!$N$6="All",1,--('Cleaned Data'!$Q$2:$Q$34='Sales Dashboard'!$N$6))*--('Cleaned Data'!$B$2:$B$34>='Sales Dashboard'!$B$8)*--('Cleaned Data'!$B$2:$B$34<='Sales Dashboard'!$F$8))*--('Cleaned Data'!$F$2:$F$34=A28)))) -> 2 | H28: =IFERROR(D28/B28,0) -> 0.32142857
A29: Desk | B29: =SUMIFS('Cleaned Data'!$K$2:$K$34,'Cleaned Data'!$H$2:$H$34,IF('Sales Dashboard'!$B$6="All","*",'Sales Dashboard'!$B$6),'Cleaned Data'!$G$2:$G$34,IF('Sales Dashboard'!$F$6="All","*",'Sales Dashboard'!$F$6),'Cleaned Data'!$F$2:$F$34,IF('Sales Dashboard'!$J$6="All","*",'Sales Dashboard'!$J$6),'Cleaned Data'!$Q$2:$Q$34,IF('Sales Dashboard'!$N$6="All","*",'Sales Dashboard'!$N$6),'Cleaned Data'!$B$2:$B$34,">="&'Sales Dashboard'!$B$8,'Cleaned Data'!$B$2:$B$34,"<="&'Sales Dashboard'!$F$8,'Cleaned Data'!$F$2:$F$34,A29) -> 26500 | C29: =SUMIFS('Cleaned Data'!$L$2:$L$34,'Cleaned Data'!$H$2:$H$34,IF('Sales Dashboard'!$B$6="All","*",'Sales Dashboard'!$B$6),'Cleaned Data'!$G$2:$G$34,IF('Sales Dashboard'!$F$6="All","*",'Sales Dashboard'!$F$6),'Cleaned Data'!$F$2:$F$34,IF('Sales Dashboard'!$J$6="All","*",'Sales Dashboard'!$J$6),'Cleaned Data'!$Q$2:$Q$34,IF('Sales Dashboard'!$N$6="All","*",'Sales Dashboard'!$N$6),'Cleaned Data'!$B$2:$B$34,">="&'Sales Dashboard'!$B$8,'Cleaned Data'!$B$2:$B$34,"<="&'Sales Dashboard'!$F$8,'Cleaned Data'!$F$2:$F$34,A29) -> 19000 | D29: =SUMIFS('Cleaned Data'!$M$2:$M$34,'Cleaned Data'!$H$2:$H$34,IF('Sales Dashboard'!$B$6="All","*",'Sales Dashboard'!$B$6),'Cleaned Data'!$G$2:$G$34,IF('Sales Dashboard'!$F$6="All","*",'Sales Dashboard'!$F$6),'Cleaned Data'!$F$2:$F$34,IF('Sales Dashboard'!$J$6="All","*",'Sales Dashboard'!$J$6),'Cleaned Data'!$Q$2:$Q$34,IF('Sales Dashboard'!$N$6="All","*",'Sales Dashboard'!$N$6),'Cleaned Data'!$B$2:$B$34,">="&'Sales Dashboard'!$B$8,'Cleaned Data'!$B$2:$B$34,"<="&'Sales Dashboard'!$F$8,'Cleaned Data'!$F$2:$F$34,A29) -> 7500 | E29: =SUMIFS('Cleaned Data'!$I$2:$I$34,'Cleaned Data'!$H$2:$H$34,IF('Sales Dashboard'!$B$6="All","*",'Sales Dashboard'!$B$6),'Cleaned Data'!$G$2:$G$34,IF('Sales Dashboard'!$F$6="All","*",'Sales Dashboard'!$F$6),'Cleaned Data'!$F$2:$F$34,IF('Sales Dashboard'!$J$6="All","*",'Sales Dashboard'!$J$6),'Cleaned Data'!$Q$2:$Q$34,IF('Sales Dashboard'!$N$6="All","*",'Sales Dashboard'!$N$6),'Cleaned Data'!$B$2:$B$34,">="&'Sales Dashboard'!$B$8,'Cleaned Data'!$B$2:$B$34,"<="&'Sales Dashboard'!$F$8,'Cleaned Data'!$F$2:$F$34,A29) -> 3 | F29: =COUNTIFS('Cleaned Data'!$H$2:$H$34,IF('Sales Dashboard'!$B$6="All","*",'Sales Dashboard'!$B$6),'Cleaned Data'!$G$2:$G$34,IF('Sales Dashboard'!$F$6="All","*",'Sales Dashboard'!$F$6),'Cleaned Data'!$F$2:$F$34,IF('Sales Dashboard'!$J$6="All","*",'Sales Dashboard'!$J$6),'Cleaned Data'!$Q$2:$Q$34,IF('Sales Dashboard'!$N$6="All","*",'Sales Dashboard'!$N$6),'Cleaned Data'!$B$2:$B$34,">="&'Sales Dashboard'!$B$8,'Cleaned Data'!$B$2:$B$34,"<="&'Sales Dashboard'!$F$8,'Cleaned Data'!$F$2:$F$34,A29) -> 2 | G29: =SUMPRODUCT(((IF('Sales Dashboard'!$B$6="All",1,--('Cleaned Data'!$H$2:$H$34='Sales Dashboard'!$B$6))*IF('Sales Dashboard'!$F$6="All",1,--('Cleaned Data'!$G$2:$G$34='Sales Dashboard'!$F$6))*IF('Sales Dashboard'!$J$6="All",1,--('Cleaned Data'!$F$2:$F$34='Sales Dashboard'!$J$6))*IF('Sales Dashboard'!$N$6="All",1,--('Cleaned Data'!$Q$2:$Q$34='Sales Dashboard'!$N$6))*--('Cleaned Data'!$B$2:$B$34>='Sales Dashboard'!$B$8)*--('Cleaned Data'!$B$2:$B$34<='Sales Dashboard'!$F$8))*--('Cleaned Data'!$F$2:$F$34=A29))/(COUNTIFS('Cleaned Data'!$A$2:$A$34,'Cleaned Data'!$A$2:$A$34,'Cleaned Data'!$H$2:$H$34,IF('Sales Dashboard'!$B$6="All","*",'Sales Dashboard'!$B$6),'Cleaned Data'!$G$2:$G$34,IF('Sales Dashboard'!$F$6="All","*",'Sales Dashboard'!$F$6),'Cleaned Data'!$F$2:$F$34,IF('Sales Dashboard'!$J$6="All","*",'Sales Dashboard'!$J$6),'Cleaned Data'!$Q$2:$Q$34,IF('Sales Dashboard'!$N$6="All","*",'Sales Dashboard'!$N$6),'Cleaned Data'!$B$2:$B$34,">="&'Sales Dashboard'!$B$8,'Cleaned Data'!$B$2:$B$34,"<="&'Sales Dashboard'!$F$8,'Cleaned Data'!$F$2:$F$34,A29)+1-((IF('Sales Dashboard'!$B$6="All",1,--('Cleaned Data'!$H$2:$H$34='Sales Dashboard'!$B$6))*IF('Sales Dashboard'!$F$6="All",1,--('Cleaned Data'!$G$2:$G$34='Sales Dashboard'!$F$6))*IF('Sales Dashboard'!$J$6="All",1,--('Cleaned Data'!$F$2:$F$34='Sales Dashboard'!$J$6))*IF('Sales Dashboard'!$N$6="All",1,--('Cleaned Data'!$Q$2:$Q$34='Sales Dashboard'!$N$6))*--('Cleaned Data'!$B$2:$B$34>='Sales Dashboard'!$B$8)*--('Cleaned Data'!$B$2:$B$34<='Sales Dashboard'!$F$8))*--('Cleaned Data'!$F$2:$F$34=A29)))) -> 2 | H29: =IFERROR(D29/B29,0) -> 0.28301887
A30: Headphones | B30: =SUMIFS('Cleaned Data'!$K$2:$K$34,'Cleaned Data'!$H$2:$H$34,IF('Sales Dashboard'!$B$6="All","*",'Sales Dashboard'!$B$6),'Cleaned Data'!$G$2:$G$34,IF('Sales Dashboard'!$F$6="All","*",'Sales Dashboard'!$F$6),'Cleaned Data'!$F$2:$F$34,IF('Sales Dashboard'!$J$6="All","*",'Sales Dashboard'!$J$6),'Cleaned Data'!$Q$2:$Q$34,IF('Sales Dashboard'!$N$6="All","*",'Sales Dashboard'!$N$6),'Cleaned Data'!$B$2:$B$34,">="&'Sales Dashboard'!$B$8,'Cleaned Data'!$B$2:$B$34,"<="&'Sales Dashboard'!$F$8,'Cleaned Data'!$F$2:$F$34,A30) -> 22500 | C30: =SUMIFS('Cleaned Data'!$L$2:$L$34,'Cleaned Data'!$H$2:$H$34,IF('Sales Dashboard'!$B$6="All","*",'Sales Dashboard'!$B$6),'Cleaned Data'!$G$2:$G$34,IF('Sales Dashboard'!$F$6="All","*",'Sales Dashboard'!$F$6),'Cleaned Data'!$F$2:$F$34,IF('Sales Dashboard'!$J$6="All","*",'Sales Dashboard'!$J$6),'Cleaned Data'!$Q$2:$Q$34,IF('Sales Dashboard'!$N$6="All","*",'Sales Dashboard'!$N$6),'Cleaned Data'!$B$2:$B$34,">="&'Sales Dashboard'!$B$8,'Cleaned Data'!$B$2:$B$34,"<="&'Sales Dashboard'!$F$8,'Cleaned Data'!$F$2:$F$34,A30) -> 14500 | D30: =SUMIFS('Cleaned Data'!$M$2:$M$34,'Cleaned Data'!$H$2:$H$34,IF('Sales Dashboard'!$B$6="All","*",'Sales Dashboard'!$B$6),'Cleaned Data'!$G$2:$G$34,IF('Sales Dashboard'!$F$6="All","*",'Sales Dashboard'!$F$6),'Cleaned Data'!$F$2:$F$34,IF('Sales Dashboard'!$J$6="All","*",'Sales Dashboard'!$J$6),'Cleaned Data'!$Q$2:$Q$34,IF('Sales Dashboard'!$N$6="All","*",'Sales Dashboard'!$N$6),'Cleaned Data'!$B$2:$B$34,">="&'Sales Dashboard'!$B$8,'Cleaned Data'!$B$2:$B$34,"<="&'Sales Dashboard'!$F$8,'Cleaned Data'!$F$2:$F$34,A30) -> 8000 | E30: =SUMIFS('Cleaned Data'!$I$2:$I$34,'Cleaned Data'!$H$2:$H$34,IF('Sales Dashboard'!$B$6="All","*",'Sales Dashboard'!$B$6),'Cleaned Data'!$G$2:$G$34,IF('Sales Dashboard'!$F$6="All","*",'Sales Dashboard'!$F$6),'Cleaned Data'!$F$2:$F$34,IF('Sales Dashboard'!$J$6="All","*",'Sales Dashboard'!$J$6),'Cleaned Data'!$Q$2:$Q$34,IF('Sales Dashboard'!$N$6="All","*",'Sales Dashboard'!$N$6),'Cleaned Data'!$B$2:$B$34,">="&'Sales Dashboard'!$B$8,'Cleaned Data'!$B$2:$B$34,"<="&'Sales Dashboard'!$F$8,'Cleaned Data'!$F$2:$F$34,A30) -> 8 | F30: =COUNTIFS('Cleaned Data'!$H$2:$H$34,IF('Sales Dashboard'!$B$6="All","*",'Sales Dashboard'!$B$6),'Cleaned Data'!$G$2:$G$34,IF('Sales Dashboard'!$F$6="All","*",'Sales Dashboard'!$F$6),'Cleaned Data'!$F$2:$F$34,IF('Sales Dashboard'!$J$6="All","*",'Sales Dashboard'!$J$6),'Cleaned Data'!$Q$2:$Q$34,IF('Sales Dashboard'!$N$6="All","*",'Sales Dashboard'!$N$6),'Cleaned Data'!$B$2:$B$34,">="&'Sales Dashboard'!$B$8,'Cleaned Data'!$B$2:$B$34,"<="&'Sales Dashboard'!$F$8,'Cleaned Data'!$F$2:$F$34,A30) -> 2 | G30: =SUMPRODUCT(((IF('Sales Dashboard'!$B$6="All",1,--('Cleaned Data'!$H$2:$H$34='Sales Dashboard'!$B$6))*IF('Sales Dashboard'!$F$6="All",1,--('Cleaned Data'!$G$2:$G$34='Sales Dashboard'!$F$6))*IF('Sales Dashboard'!$J$6="All",1,--('Cleaned Data'!$F$2:$F$34='Sales Dashboard'!$J$6))*IF('Sales Dashboard'!$N$6="All",1,--('Cleaned Data'!$Q$2:$Q$34='Sales Dashboard'!$N$6))*--('Cleaned Data'!$B$2:$B$34>='Sales Dashboard'!$B$8)*--('Cleaned Data'!$B$2:$B$34<='Sales Dashboard'!$F$8))*--('Cleaned Data'!$F$2:$F$34=A30))/(COUNTIFS('Cleaned Data'!$A$2:$A$34,'Cleaned Data'!$A$2:$A$34,'Cleaned Data'!$H$2:$H$34,IF('Sales Dashboard'!$B$6="All","*",'Sales Dashboard'!$B$6),'Cleaned Data'!$G$2:$G$34,IF('Sales Dashboard'!$F$6="All","*",'Sales Dashboard'!$F$6),'Cleaned Data'!$F$2:$F$34,IF('Sales Dashboard'!$J$6="All","*",'Sales Dashboard'!$J$6),'Cleaned Data'!$Q$2:$Q$34,IF('Sales Dashboard'!$N$6="All","*",'Sales Dashboard'!$N$6),'Cleaned Data'!$B$2:$B$34,">="&'Sales Dashboard'!$B$8,'Cleaned Data'!$B$2:$B$34,"<="&'Sales Dashboard'!$F$8,'Cleaned Data'!$F$2:$F$34,A30)+1-((IF('Sales Dashboard'!$B$6="All",1,--('Cleaned Data'!$H$2:$H$34='Sales Dashboard'!$B$6))*IF('Sales Dashboard'!$F$6="All",1,--('Cleaned Data'!$G$2:$G$34='Sales Dashboard'!$F$6))*IF('Sales Dashboard'!$J$6="All",1,--('Cleaned Data'!$F$2:$F$34='Sales Dashboard'!$J$6))*IF('Sales Dashboard'!$N$6="All",1,--('Cleaned Data'!$Q$2:$Q$34='Sales Dashboard'!$N$6))*--('Cleaned Data'!$B$2:$B$34>='Sales Dashboard'!$B$8)*--('Cleaned Data'!$B$2:$B$34<='Sales Dashboard'!$F$8))*--('Cleaned Data'!$F$2:$F$34=A30)))) -> 2 | H30: =IFERROR(D30/B30,0) -> 0.35555556
